Promise.resolve("asyncfail")
    .then(response => {
        console.log(response);
        throw new Error("#1 fail");
    })
    .then(response => {
        console.log(response);
    })
    .catch(err => {
        console.error("error", err.message);
    })
    .then(response => {
        console.log("hi am I still needed?", response);
        return "done";
    })
    .catch(err => {
        console.error(err);
        return "failed";
    });
